#VRML_SIM R2019a utf8
WorldInfo {
}
Viewpoint {
  orientation -0.0010008552520730746 -0.9712427669213571 -0.23808923955464847 3.1334270764733554
  position 0.09308029314158028 0.364949039659274 -0.5153375680343067
}
TexturedBackground {
}
TexturedBackgroundLight {
}
Floor {
}
Robot {
  translation 0 0.075 0
  children [
    DEF BODY_GROUP Group {
      children [
        Shape {
          appearance PBRAppearance {
            baseColor 0.12549019607843137 0.2901960784313726 0.5294117647058824
            roughness 1
            metalness 0
          }
          geometry Box {
            size 0.25 0.08 0.1
          }
        }
        Transform {
          translation 0.1075 -0.0575 0
          children [
            Shape {
              appearance PBRAppearance {
                baseColor 0.9294117647058824 0.8313725490196079 0
                roughness 1
                metalness 0
              }
              geometry Sphere {
                radius 0.0175
                subdivision 2
              }
            }
          ]
        }
      ]
    }
    HingeJoint {
      jointParameters HingeJointParameters {
        axis 0 0 1
        anchor -0.05 0 0.065
      }
      device [
        RotationalMotor {
          name "motor_right"
          maxVelocity 52.35
          maxTorque 0.593170353999997
        }
        PositionSensor {
          name "position_sensor_right"
          resolution 0.005235833
        }
      ]
      endPoint Solid {
        translation -0.05 0 0.065
        rotation 1 0 0 1.5779999999999998
        children [
          DEF WHEEL_SH Shape {
            appearance DEF COLOR_WHEEL PBRAppearance {
              baseColor 0.8 0 0
              roughness 1
              metalness 0
            }
            geometry Cylinder {
              height 0.03
              radius 0.075
            }
          }
        ]
        boundingObject USE WHEEL_SH
        physics Physics {
        }
      }
    }
    HingeJoint {
      jointParameters HingeJointParameters {
        axis 0 0 1
        anchor -0.05 0 -0.065
      }
      device [
        RotationalMotor {
          name "motor_left"
          maxVelocity 523.599
          maxTorque 0.03
        }
      ]
      endPoint Solid {
        translation -0.05 0 -0.065
        rotation 1 0 0 1.5699996938995748
        children [
          USE WHEEL_SH
        ]
        name "solid(1)"
        boundingObject USE WHEEL_SH
        physics Physics {
        }
      }
    }
    DistanceSensor {
      translation 0.125 0 0
      children [
        Shape {
          appearance USE COLOR_WHEEL
          geometry DEF DIST_SEN Box {
            size 0.01 0.01 0.01
          }
        }
      ]
      name "distance_sensor"
      boundingObject USE DIST_SEN
      lookupTable [
        0 0 0
        0.02 0 0
        5 1660 0
      ]
      resolution 1
    }
  ]
  boundingObject USE BODY_GROUP
  physics Physics {
  }
  controller "Crazybot"
}
