#VRML_SIM R2019a utf8
WorldInfo {
}
Viewpoint {
  orientation 0.18570391075073212 -0.98109834719615 -0.054406715218498686 5.702804761944932
  position 0.8285175313403393 0.42802105755752945 1.2197123092165973
}
TexturedBackground {
}
TexturedBackgroundLight {
}
Floor {
}
Robot {
  translation 0 0.075 0
  children [
    DEF BODY_GROUP Group {
      children [
        Shape {
          appearance PBRAppearance {
            baseColor 0.12549019607843137 0.2901960784313726 0.5294117647058824
            roughness 1
            metalness 0
          }
          geometry Box {
            size 0.25 0.08 0.1
          }
        }
        Transform {
          translation 0.1075 -0.0575 0
          children [
            Shape {
              appearance PBRAppearance {
                baseColor 0.9294117647058824 0.8313725490196079 0
                roughness 1
                metalness 0
              }
              geometry Sphere {
                radius 0.0175
                subdivision 2
              }
            }
          ]
        }
      ]
    }
    HingeJoint {
      jointParameters HingeJointParameters {
        axis 0 0 1
        anchor -0.05 0 0.065
      }
      endPoint Solid {
        translation -0.05 0 0.065
        rotation 1 0 0 1.578
        children [
          DEF WHEEL_SH Shape {
            appearance DEF COLOR_WHEEL PBRAppearance {
              baseColor 0.8 0 0
              roughness 1
              metalness 0
            }
            geometry Cylinder {
              height 0.03
              radius 0.075
            }
          }
        ]
        boundingObject USE WHEEL_SH
      }
    }
    HingeJoint {
      jointParameters HingeJointParameters {
        axis 0 0 1
        anchor -0.05 0 -0.065
      }
      endPoint Solid {
        translation -0.05 0 -0.065
        rotation 1 0 0 1.5699996938995748
        children [
          USE WHEEL_SH
        ]
        name "solid(1)"
        boundingObject USE WHEEL_SH
      }
    }
  ]
  boundingObject USE BODY_GROUP
  physics Physics {
  }
}
