#VRML_SIM R2019a utf8
WorldInfo {
}
Viewpoint {
  orientation -0.19733137713786125 -0.9763339989308764 -0.08850000072609426 0.8612129784740865
  position -1.5280040663845875 0.4865078279212693 1.3147149751595983
}
TexturedBackground {
}
TexturedBackgroundLight {
}
Floor {
}
Robot {
  translation 0 0.085 0
  children [
    DEF BODY_GROUP Group {
      children [
        Shape {
          appearance PBRAppearance {
            baseColor 0.12549019607843137 0.2901960784313726 0.5294117647058824
            roughness 1
            metalness 0
          }
          geometry Box {
            size 0.25 0.08 0.1
          }
        }
        Transform {
          translation 0.1075 -0.0575 0
          children [
            Shape {
              appearance PBRAppearance {
                baseColor 0.9294117647058824 0.8313725490196079 0
                roughness 1
                metalness 0
              }
              geometry Sphere {
                radius 0.0175
                subdivision 2
              }
            }
          ]
        }
      ]
    }
    HingeJoint {
      jointParameters HingeJointParameters {
        axis 0 0 1
        anchor -0.05 0 0.065
      }
      device [
        RotationalMotor {
          name "motor_right"
          maxVelocity 52.35
          maxTorque 0.593170353999997
        }
        PositionSensor {
          name "position_sensor_right"
          resolution 1
        }
      ]
      endPoint Solid {
        translation -0.050002580286428164 3.780897306187956e-05 0.06500000195888461
        rotation 0.9984367074513493 -0.03966513865991629 -0.03938042646796097 1.5795644029284133
        children [
          DEF WHEEL_SH Shape {
            appearance DEF COLOR_WHEEL PBRAppearance {
              baseColor 0.8 0 0
              roughness 1
              metalness 0
            }
            geometry Cylinder {
              height 0.03
              radius 0.075
            }
          }
        ]
        boundingObject USE WHEEL_SH
        physics Physics {
        }
      }
    }
    HingeJoint {
      jointParameters HingeJointParameters {
        axis 0 0 1
        anchor -0.05 0 -0.065
      }
      device [
        RotationalMotor {
          name "motor_left"
          maxVelocity 52.4
          maxTorque 0.593
        }
        PositionSensor {
          name "position_sensor_left"
          resolution 0.00524
        }
      ]
      endPoint Solid {
        translation -0.050002315997806586 3.863517469715169e-05 -0.06499999705275784
        rotation 0.998417954521537 -0.03974335679151976 -0.03977503840314985 1.5715830040453898
        children [
          USE WHEEL_SH
        ]
        name "solid(1)"
        boundingObject USE WHEEL_SH
        physics Physics {
        }
      }
    }
    DistanceSensor {
      translation 0.125 0 0
      children [
        Shape {
          appearance USE COLOR_WHEEL
          geometry DEF DIST_SEN Box {
            size 0.01 0.01 0.01
          }
        }
      ]
      name "distance_sensor"
      lookupTable [
        0 0 0
        0.02 0 0
        5 1660 0
      ]
      resolution 1
    }
  ]
  boundingObject USE BODY_GROUP
  physics Physics {
    density 1100
  }
  controller "Crazybot"
}
Solid {
  translation 0.62 0.2 0
  children [
    Shape {
      appearance PBRAppearance {
        baseColor 0.45098039215686275 0.8235294117647058 0.08627450980392157
        roughness 1
        metalness 0
      }
      geometry Box {
        size 0.4 0.4 0.4
      }
    }
  ]
}
