#VRML_SIM R2019a utf8
WorldInfo {
}
Viewpoint {
  orientation -0.07724710877881215 0.9969580790745695 0.01036690663886619 0.2676191299438586
  position 0.2507239507439579 0.10806934920983761 0.6332380920358878
}
TexturedBackground {
}
TexturedBackgroundLight {
}
Floor {
}
Robot {
  translation 0 0.075 0
  children [
    DEF BODY_GROUP Group {
      children [
        Shape {
          appearance PBRAppearance {
            baseColor 0.12549019607843137 0.2901960784313726 0.5294117647058824
            roughness 1
            metalness 0
          }
          geometry Box {
            size 0.25 0.08 0.1
          }
        }
        Transform {
          translation 0.1075 -0.0575 0
          children [
            Shape {
              appearance PBRAppearance {
                baseColor 0.9294117647058824 0.8313725490196079 0
                roughness 1
                metalness 0
              }
              geometry Sphere {
                radius 0.0175
                subdivision 2
              }
            }
          ]
        }
      ]
    }
    HingeJoint {
      jointParameters HingeJointParameters {
        axis 0 0 1
        anchor -0.05 0 0.065
      }
      device [
        RotationalMotor {
          name "motor_right"
          maxVelocity 52.35
          maxTorque 0.593170353999997
        }
        PositionSensor {
          name "position_sensor_right"
          resolution 0.005235833
        }
      ]
      endPoint Solid {
        translation -0.05000083806152519 1.3046599663638971e-05 0.0649999995234742
        rotation 1 1.5870661669334776e-09 -1.9672302125085397e-09 1.5779999776543139
        children [
          DEF WHEEL_SH Shape {
            appearance DEF COLOR_WHEEL PBRAppearance {
              baseColor 0.8 0 0
              roughness 1
              metalness 0
            }
            geometry Cylinder {
              height 0.03
              radius 0.075
            }
          }
        ]
        boundingObject USE WHEEL_SH
        physics Physics {
        }
      }
    }
    HingeJoint {
      jointParameters HingeJointParameters {
        axis 0 0 1
        anchor -0.05 0 -0.065
      }
      device [
        RotationalMotor {
          name "motor_left"
          maxVelocity 52.4
          maxTorque 0.593
        }
        PositionSensor {
          name "position_sensor_left"
          resolution 0.00524
        }
      ]
      endPoint Solid {
        translation -0.050000830391737056 1.329150513769556e-05 -0.064999999543304
        rotation 1 3.656383177911341e-09 -4.0262105148082014e-09 1.5699997005667823
        children [
          USE WHEEL_SH
        ]
        name "solid(1)"
        boundingObject USE WHEEL_SH
        physics Physics {
        }
      }
    }
    DistanceSensor {
      translation 0.125 0 0
      children [
        Shape {
          appearance USE COLOR_WHEEL
          geometry DEF DIST_SEN Box {
            size 0.01 0.01 0.01
          }
        }
      ]
      name "distance_sensor"
      boundingObject USE DIST_SEN
      lookupTable [
        0 0 0
        0.02 0 0
        5 1660 0
      ]
      resolution 1
    }
  ]
  boundingObject USE BODY_GROUP
  physics Physics {
    density 1100
  }
  controller "Crazybot"
}
